Workbook

Sheet Kalkulator
B1: HS 3D Kalkulator
B2: Oranžna polja spreminjaš, ostalo se izračuna samo.
B3: Podatki o projektu | E3: KONČNA CENA | G3: CENA NA KOS
B4: Ime projekta | C4: Nosilci lučk – 2 leva + 2 desna | E4: =F44 | G4: =F45
B5: Stranka | C5: Demo | E5: =IF($C$7="Zase","Zase: prikazani so dejanski stroški",IF(F41,"Upoštevano minimalno naročilo",IF('Poslovne nastavitve'!$B$8="DA","Z DDV","DDV ni obračunan")))
B6: Datum | C6: 46320 | E6: STROŠKI TISKANJA | G6: VREDNOST STORITEV
B7: Način obračuna | C7: Stranka | E7: =F26 | G7: =IF($C$7="Zase",F48,F35+F36)
B8: Vrsta naročila | C8: Kombinirano
B9: 3D-tiskanje | E9: PREDVIDENI ZASLUŽEK | G9: ZASLUŽEK NA URO
B10: Tiskalnik | C10: Bambu Lab X2D Combo | E10: =F52 | G10: =F53
B11: Material | C11: Bambu ASA | E11: Izračun
B12: Število kosov | C12: 4 | E12: Čas tiska skupaj (h) | F12: =IF($C$16="DA",$C$17+$C$18/60,$C$12*($C$14+$C$15/60))
B13: Teža kosa (g) | C13: 192 | E13: Filament skupaj (kg) | F13: =($C$12*$C$13+$C$19)/1000
B14: Čas kosa – ure | C14: 4 | E14: Vrsta materiala | F14: =INDEX(Materiali!$C:$C,MATCH($C$11,Materiali!$A:$A,0))
B15: Čas kosa – minute | C15: 42 | E15: Cena materiala €/kg | F15: =INDEX(Materiali!$H:$H,MATCH($C$11,Materiali!$A:$A,0))
B16: Vnesem skupen čas serije | C16: NE | E16: Vrstica tiskalnika | F16: =MATCH($C$10,Tiskalniki!$A:$A,0)
B17: Skupen čas – ure | C17: 0 | E17: Moč (W) | F17: =IFERROR(IF(ISNUMBER(INDEX(Tiskalniki!$F:$K,F16,MATCH(F14,Tiskalniki!$F$3:$K$3,0))),INDEX(Tiskalniki!$F:$K,F16,MATCH(F14,Tiskalniki!$F$3:$K$3,0)),N(INDEX(Tiskalniki!$E:$E,F16))),N(INDEX(Tiskalniki!$E:$E,F16)))
B18: Skupen čas – minute | C18: 0 | E18: Amortizacija €/h | F18: =INDEX(Tiskalniki!$L:$L,F16)
B19: Dodatna poraba (podpore, purge, AMS) g | C19: 0 | E19: 1. Stroški tiskanja
B20: Potrošni material (lepilo …) € | C20: 3.4 | E20: Material | F20: =F13*F15
B21: Ostali neposredni stroški tiska € | C21: 0 | E21: Elektrika | F21: =F12*F17/1000*'Poslovne nastavitve'!$B$6
B22: Rezerva za neuspele tiske % | C22: ='Cenik storitev'!$B$11 | E22: Amortizacija tiskalnika | F22: =F12*F18
B23: Pribitek na stroške tiska % | C23: ='Cenik storitev'!$B$10 | E23: Potrošni + ostali neposredni | F23: =$C$20+$C$21
B24: Ročni stroški tiska € (prazno = izračun) | E24: Stroški pred rezervo | F24: =SUM(F20:F23)
B25: Storitve | E25: Rezerva | F25: =F24*$C$22/100
B26: 3D-skeniranje na terenu (h) | C26: 1 | E26: STROŠKI TISKANJA | F26: =IF(ISNUMBER($C$24),$C$24,F24+F25)
B27: Urejanje skena (h) | C27: 1 | E27: Pribitek % (samo Stranka) | F27: =IF($C$7="Stranka",$C$23,0)
B28: CAD-modeliranje (h) | C28: 0.75 | E28: Pribitek € (Prijatelj: ure tiska × €/h) | F28: =F26*F27/100+IF($C$7="Prijatelj",F12*'Cenik storitev'!$B$13,0)
B29: Reverse engineering (h) | C29: 0 | E29: Bruto marža tiska | F29: =IF(F30>0,F28/F30,0)
B30: Priprava tiska (h) | C30: 0.25 | E30: Prodajna cena tiska | F30: =F26+F28 | J30: Struktura cene
B31: Dodelava / podpore (h) | C31: 0.5 | E31: 2. Prodajna vrednost dela | J31: Material | K31: =F20
B32: Dodatno delo (h) | C32: 0 | E32: Storitve po ceniku | F32: =($C$26*'Cenik storitev'!$B$3+$C$27*'Cenik storitev'!$B$4)*(1-Datoteke!$F$26)+($C$28*'Cenik storitev'!$B$5+$C$29*'Cenik storitev'!$B$6)*(1-Datoteke!$F$27)+$C$30*'Cenik storitev'!$B$7+$C$31*'Cenik storitev'!$B$7+$C$32*$C$33 | J32: Elektrika | K32: =F21
B33: Dodatno delo – cena €/h | C33: ='Cenik storitev'!$B$7 | E33: Popust prijatelj % | F33: =IF($C$7="Prijatelj",$C$34/100,0) | J33: Amortizacija | K33: =F22
B34: Prijateljski popust na storitve % | C34: ='Cenik storitev'!$B$12 | E34: Popust / ni obračunano (Zase) | F34: =IF($C$7="Zase",F32,F32*F33) | J34: Potrošni material | K34: =F23
B35: Ostalo | E35: Storitve (obračunano) | F35: =F32-F34 | J35: Rezerva | K35: =F25
B36: Prevoz (km) | C36: 0 | E36: Digitalne datoteke | F36: =IF($C$7="Zase",0,(Datoteke!$F$10+Datoteke!$F$25)*(1-F33)) | J36: Aktivno delo | K36: =F35+F36
B37: Pakiranje € | C37: 0 | E37: Prevoz | F37: =$C$36*'Cenik storitev'!$B$8 | J37: Pribitek | K37: =F28
B38: Dostava € | C38: 0 | E38: Pakiranje + dostava + ostalo | F38: =$C$37+$C$38+$C$39 | J38: Prevoz in ostalo | K38: =F37+F38
B39: Ostali stroški € | C39: 0 | E39: Popust | F39: =IF($C$7="Zase",0,$C$40)
B40: Popust € | C40: 0 | E40: Vmesna vsota | F40: =F30+F35+F36+F37+F38-F39
...

Sheet Tiskalniki
A1: Tiskalniki
F2: Moč po materialu (W) – prazno = privzeto
A3: Naziv | B3: Nabavna cena | C3: Življ. doba (h) | D3: Servis v dobi | E3: Moč privzeto (W) | F3: PLA | G3: PETG | H3: ASA | I3: PC | J3: TPU | K3: PETG-CF | L3: Amortizacija €/h
A4: Bambu Lab X2D Combo | B4: 870.4 | C4: 3000 | D4: 200 | E4: 450 | H4: 450 | L4: =IF(C4>0,(B4+D4)/C4,0)
A5: Prusa CORE One INDX | B5: 2249 | C5: 3000 | D5: 100 | L5: =IF(C5>0,(B5+D5)/C5,0)
A6: Elegoo Mars 2 Pro | B6: 450 | C6: 3000 | D6: 200 | L6: =IF(C6>0,(B6+D6)/C6,0)
A7: Formlabs Form Studio 1 | B7: 1650 | C7: 3000 | D7: 200 | L7: =IF(C7>0,(B7+D7)/C7,0)
L8: =IF(A8="","",IF(C8>0,(B8+D8)/C8,0))
L9: =IF(A9="","",IF(C9>0,(B9+D9)/C9,0))
L10: =IF(A10="","",IF(C10>0,(B10+D10)/C10,0))
L11: =IF(A11="","",IF(C11>0,(B11+D11)/C11,0))
L12: =IF(A12="","",IF(C12>0,(B12+D12)/C12,0))
L13: =IF(A13="","",IF(C13>0,(B13+D13)/C13,0))
L14: =IF(A14="","",IF(C14>0,(B14+D14)/C14,0))
L15: =IF(A15="","",IF(C15>0,(B15+D15)/C15,0))
A17: Moči so ocene, dokler jih ne izmeriš. Prazne vrstice 8–15 so za nove tiskalnike.

Sheet Materiali
A1: Materiali
A3: Naziv | B3: Proizvajalec | C3: Vrsta | D3: Neto masa (g) | E3: Redna cena koluta | F3: Akcijska / bulk cena | G3: Uporabi | H3: €/kg | I3: Temp. sušenja | J3: Akcija / bulk | K3: Vir cene
A4: Bambu PLA Basic | B4: Bambu Lab | C4: PLA | D4: 1000 | E4: 13 | G4: Redna | H4: =IF(OR(A4="",D4<=0),"",IF(AND(G4="Akcijska",ISNUMBER(F4)),F4,E4)/(D4/1000))
A5: Bambu PETG HF | B5: Bambu Lab | C5: PETG | D5: 1000 | E5: 13 | G5: Redna | H5: =IF(OR(A5="",D5<=0),"",IF(AND(G5="Akcijska",ISNUMBER(F5)),F5,E5)/(D5/1000))
A6: Bambu ASA | B6: Bambu Lab | C6: ASA | D6: 1000 | E6: 26.64 | G6: Redna | H6: =IF(OR(A6="",D6<=0),"",IF(AND(G6="Akcijska",ISNUMBER(F6)),F6,E6)/(D6/1000))
A7: Prusament PLA | B7: Prusa | C7: PLA | D7: 1000 | E7: 32 | G7: Redna | H7: =IF(OR(A7="",D7<=0),"",IF(AND(G7="Akcijska",ISNUMBER(F7)),F7,E7)/(D7/1000))
A8: Prusament PETG | B8: Prusa | C8: PETG | D8: 1000 | E8: 32 | G8: Redna | H8: =IF(OR(A8="",D8<=0),"",IF(AND(G8="Akcijska",ISNUMBER(F8)),F8,E8)/(D8/1000))
A9: Prusament ASA | B9: Prusa | C9: ASA | D9: 1000 | E9: 32 | G9: Redna | H9: =IF(OR(A9="",D9<=0),"",IF(AND(G9="Akcijska",ISNUMBER(F9)),F9,E9)/(D9/1000))
A10: Plastika Trček PLA | B10: Plastika Trček | C10: PLA | D10: 1000 | E10: 21 | G10: Redna | H10: =IF(OR(A10="",D10<=0),"",IF(AND(G10="Akcijska",ISNUMBER(F10)),F10,E10)/(D10/1000))
A11: Plastika Trček PETG | B11: Plastika Trček | C11: PETG | D11: 1000 | E11: 22 | G11: Redna | H11: =IF(OR(A11="",D11<=0),"",IF(AND(G11="Akcijska",ISNUMBER(F11)),F11,E11)/(D11/1000))
A12: Prusament PC Blend | B12: Prusa | C12: PC | D12: 1000 | E12: 46.39 | G12: Redna | H12: =IF(OR(A12="",D12<=0),"",IF(AND(G12="Akcijska",ISNUMBER(F12)),F12,E12)/(D12/1000))
A13: Plastika Trček TPU | B13: Plastika Trček | C13: TPU | D13: 1000 | E13: 38.57 | G13: Redna | H13: =IF(OR(A13="",D13<=0),"",IF(AND(G13="Akcijska",ISNUMBER(F13)),F13,E13)/(D13/1000))
A14: Prusament PETG-CF | B14: Prusa | C14: PETG-CF | D14: 1000 | E14: 60 | G14: Redna | H14: =IF(OR(A14="",D14<=0),"",IF(AND(G14="Akcijska",ISNUMBER(F14)),F14,E14)/(D14/1000))
A15: Bambu PLA Basic (1 kg) | B15: Bambu Lab | C15: PLA | D15: 1000 | E15: 16.99 | F15: 11.04 | G15: Redna | H15: =IF(OR(A15="",D15<=0),"",IF(AND(G15="Akcijska",ISNUMBER(F15)),F15,E15)/(D15/1000)) | J15: Bulk 10+ | K15: https://eu.store.bambulab.com/products/pla-basic-filament
A16: Bambu PETG HF (1 kg) | B16: Bambu Lab | C16: PETG | D16: 1000 | E16: 19.99 | F16: 12.99 | G16: Redna | H16: =IF(OR(A16="",D16<=0),"",IF(AND(G16="Akcijska",ISNUMBER(F16)),F16,E16)/(D16/1000)) | J16: Bulk 10+ | K16: https://eu.store.bambulab.com/products/petg-hf
A17: Bambu PETG Basic (1 kg) | B17: Bambu Lab | C17: PETG | D17: 1000 | E17: 15.99 | F17: 10.39 | G17: Redna | H17: =IF(OR(A17="",D17<=0),"",IF(AND(G17="Akcijska",ISNUMBER(F17)),F17,E17)/(D17/1000)) | J17: Bulk 10+ | K17: https://eu.store.bambulab.com/products/petg-basic
A18: Bambu ASA (1 kg) | B18: Bambu Lab | C18: ASA | D18: 1000 | E18: 24.99 | G18: Redna | H18: =IF(OR(A18="",D18<=0),"",IF(AND(G18="Akcijska",ISNUMBER(F18)),F18,E18)/(D18/1000)) | K18: https://eu.store.bambulab.com/products/asa-filament
A19: Bambu ABS (1 kg) | B19: Bambu Lab | C19: ABS | D19: 1000 | E19: 16.99 | F19: 11.04 | G19: Redna | H19: =IF(OR(A19="",D19<=0),"",IF(AND(G19="Akcijska",ISNUMBER(F19)),F19,E19)/(D19/1000)) | J19: Bulk 10+ | K19: https://eu.store.bambulab.com/products/abs-filament
A20: Bambu PC (1 kg) | B20: Bambu Lab | C20: PC | D20: 1000 | E20: 42.99 | G20: Redna | H20: =IF(OR(A20="",D20<=0),"",IF(AND(G20="Akcijska",ISNUMBER(F20)),F20,E20)/(D20/1000)) | K20: https://eu.store.bambulab.com/products/pc-filament
A21: Bambu PA6-CF najlon (1 kg) | B21: Bambu Lab | C21: PA | D21: 1000 | E21: 44.99 | G21: Redna | H21: =IF(OR(A21="",D21<=0),"",IF(AND(G21="Akcijska",ISNUMBER(F21)),F21,E21)/(D21/1000)) | K21: https://eu.store.bambulab.com/products/pa6-cf
A22: Prusament PLA (1 kg) | B22: Prusa | C22: PLA | D22: 1000 | E22: 32.99 | F22: 26.39 | G22: Redna | H22: =IF(OR(A22="",D22<=0),"",IF(AND(G22="Akcijska",ISNUMBER(F22)),F22,E22)/(D22/1000)) | J22: Akcija -20 % | K22: https://www.prusa3d.com/de/kategorie/prusament-pla/
A23: Prusament PETG (1 kg) | B23: Prusa | C23: PETG | D23: 1000 | E23: 32.99 | F23: 26.39 | G23: Redna | H23: =IF(OR(A23="",D23<=0),"",IF(AND(G23="Akcijska",ISNUMBER(F23)),F23,E23)/(D23/1000)) | J23: Akcija -20 % | K23: https://www.prusa3d.com/de/kategorie/prusament-petg/
A24: Prusament PETG (2 kg) | B24: Prusa | C24: PETG | D24: 2000 | E24: 54.99 | F24: 38.49 | G24: Redna | H24: =IF(OR(A24="",D24<=0),"",IF(AND(G24="Akcijska",ISNUMBER(F24)),F24,E24)/(D24/1000)) | J24: Akcija -30 % | K24: https://www.prusa3d.com/de/kategorie/prusament-petg/
A25: Prusament ASA (800 g) | B25: Prusa | C25: ASA | D25: 800 | E25: 30.99 | F25: 24.79 | G25: Redna | H25: =IF(OR(A25="",D25<=0),"",IF(AND(G25="Akcijska",ISNUMBER(F25)),F25,E25)/(D25/1000)) | J25: Akcija -20 % | K25: https://www.prusa3d.com/de/kategorie/prusament-asa/
A26: Prusament PC Blend (900 g) | B26: Prusa | C26: PC | D26: 900 | E26: 50.99 | F26: 30.59 | G26: Redna | H26: =IF(OR(A26="",D26<=0),"",IF(AND(G26="Akcijska",ISNUMBER(F26)),F26,E26)/(D26/1000)) | J26: Akcija -40 % | K26: https://www.prusa3d.com/de/kategorie/prusament-pc-blend/
A27: Prusament PA11 Natural najlon (800 g) | B27: Prusa | C27: PA | D27: 800 | E27: 107 | F27: 85.6 | G27: Redna | H27: =IF(OR(A27="",D27<=0),"",IF(AND(G27="Akcijska",ISNUMBER(F27)),F27,E27)/(D27/1000)) | J27: Akcija -20 % | K27: https://www.prusa3d.com/de/kategorie/prusament-pa-nylon/
A28: Trček PLA (1 kg) | B28: Plastika Trček | C28: PLA | D28: 1000 | E28: 19.49 | F28: 11.69 | G28: Redna | H28: =IF(OR(A28="",D28<=0),"",IF(AND(G28="Akcijska",ISNUMBER(F28)),F28,E28)/(D28/1000)) | I28: 50 °C | J28: 20+ kosov | K28: https://3dtrcek.com/sl/pla-filament
A29: Trček PLA (5 kg) | B29: Plastika Trček | C29: PLA | D29: 5000 | E29: 99.95 | G29: Redna | H29: =IF(OR(A29="",D29<=0),"",IF(AND(G29="Akcijska",ISNUMBER(F29)),F29,E29)/(D29/1000)) | I29: 50 °C | K29: https://3dtrcek.com/sl/pla-filament
A30: Trček PETG (1 kg) | B30: Plastika Trček | C30: PETG | D30: 1000 | E30: 19.49 | F30: 11.69 | G30: Redna | H30: =IF(OR(A30="",D30<=0),"",IF(AND(G30="Akcijska",ISNUMBER(F30)),F30,E30)/(D30/1000)) | I30: 60 °C, 2–4 h | J30: 20+ kosov | K30: https://3dtrcek.com/sl/petg-filament
A31: Trček PETG (10 kg) | B31: Plastika Trček | C31: PETG | D31: 10000 | E31: 188.9 | G31: Redna | H31: =IF(OR(A31="",D31<=0),"",IF(AND(G31="Akcijska",ISNUMBER(F31)),F31,E31)/(D31/1000)) | I31: 60 °C, 2–4 h | K31: https://3dtrcek.com/sl/petg-filament
A32: Trček ASA+ (800 g) | B32: Plastika Trček | C32: ASA | D32: 800 | E32: 21.9 | F32: 13.14 | G32: Redna | H32: =IF(OR(A32="",D32<=0),"",IF(AND(G32="Akcijska",ISNUMBER(F32)),F32,E32)/(D32/1000)) | I32: 60 °C, 4–8 h | J32: 20+ kosov | K32: https://3dtrcek.com/sl/asa-plus-filament
A33: Trček ABS+ (1 kg) | B33: Plastika Trček | C33: ABS | D33: 1000 | E33: 21.99 | G33: Redna | H33: =IF(OR(A33="",D33<=0),"",IF(AND(G33="Akcijska",ISNUMBER(F33)),F33,E33)/(D33/1000)) | I33: 60 °C, 4–8 h | K33: https://3dtrcek.com/sl/abs-plus-filament
A34: Trček PC (1 kg) | B34: Plastika Trček | C34: PC | D34: 1000 | E34: 47.99 | G34: Redna | H34: =IF(OR(A34="",D34<=0),"",IF(AND(G34="Akcijska",ISNUMBER(F34)),F34,E34)/(D34/1000)) | K34: https://3dtrcek.com/sl/pc-filament
A35: Trček Nylon PA12 (700 g) | B35: Plastika Trček | C35: PA | D35: 700 | E35: 33.99 | G35: Redna | H35: =IF(OR(A35="",D35<=0),"",IF(AND(G35="Akcijska",ISNUMBER(F35)),F35,E35)/(D35/1000)) | K35: https://3dtrcek.com/sl/nylon-pa-12-filament
A36: Trček PCTG (1 kg) | B36: Plastika Trček | C36: PCTG | D36: 1000 | E36: 27.99 | F36: 16.79 | G36: Redna | H36: =IF(OR(A36="",D36<=0),"",IF(AND(G36="Akcijska",ISNUMBER(F36)),F36,E36)/(D36/1000)) | J36: 20+ kosov | K36: https://3dtrcek.com/sl/pctg-filament
H37: =IF(OR(A37="",D37<=0),"",IF(AND(G37="Akcijska",ISNUMBER(F37)),F37,E37)/(D37/1000))
H38: =IF(OR(A38="",D38<=0),"",IF(AND(G38="Akcijska",ISNUMBER(F38)),F38,E38)/(D38/1000))
H39: =IF(OR(A39="",D39<=0),"",IF(AND(G39="Akcijska",ISNUMBER(F39)),F39,E39)/(D39/1000))
H40: =IF(OR(A40="",D40<=0),"",IF(AND(G40="Akcijska",ISNUMBER(F40)),F40,E40)/(D40/1000))
H41: =IF(OR(A41="",D41<=0),"",IF(AND(G41="Akcijska",ISNUMBER(F41)),F41,E41)/(D41/1000))
...

Sheet Cenik storitev
A1: Cenik storitev
A3: 3D-skeniranje | B3: 20 | C3: €/h
A4: Urejanje skena | B4: 15 | C4: €/h
A5: CAD-modeliranje | B5: 20 | C5: €/h
A6: Zahtevnejši reverse engineering | B6: 25 | C6: €/h
A7: Priprava tiska in dodelava | B7: 15 | C7: €/h
A8: Prevoz | B8: 0.3 | C8: €/km
A9: Minimalno naročilo | B9: 15 | C9: €
A10: Privzeti pribitek tiska | B10: 100 | C10: %
A11: Privzeta rezerva za neuspele tiske | B11: 10 | C11: %
A12: Prijateljski popust (samo storitve) | B12: 15 | C12: %
A13: Prijatelj: cena na uro tiskanja (namesto pribitka) | B13: 1 | C13: €/h
A14: Predaja datoteke, ko so storitve že v projektu | B14: 0 | C14: €
A15: Ponovna prodaja datoteke | B15: 30 | C15: % prvotne

Sheet Poslovne nastavitve
A1: Poslovne nastavitve
A3: Ciljna osebna postavka | B3: 15 | C3: €/h
A4: Obračunljive ure na mesec | B4: 20 | C4: h
A5: Prispevki in administracija | B5: 138.01 | C5: €/mes
A6: Cena elektrike | B6: 0.2 | C6: €/kWh
A7: Davčna rezerva (od prihodka) | B7: 0 | C7: %
A8: Obračunavam DDV | B8: NE | C8: DA/NE
A9: Stopnja DDV | B9: 22 | C9: %
A11: Davčna rezerva je privzeto 0 %, ker je odvisna od statusa (normiranec …). Vnesi svojo oceno.
A13: Mesečni načrt po ceniku
A14: Povprečna urna postavka | B14: =AVERAGE('Cenik storitev'!$B$3,'Cenik storitev'!$B$4,'Cenik storitev'!$B$5,'Cenik storitev'!$B$6,'Cenik storitev'!$B$7)
A15: Prihodek dela na mesec | B15: =B4*B14
A16: − prispevki in administracija | B16: =B5
A17: − ocena davka | B17: =B15*B7/100
A18: Predvideni osebni zaslužek | B18: =B15-B16-B17
A19: Na uro | B19: =IF(B4>0,B18/B4,0)
A20: Opozorilo | B20: =IF(B19<B3,"Cenik ne doseže ciljne postavke!","Cilj dosežen")

Sheet Datoteke
A1: Prodaja digitalnih datotek
A3: Datoteka | B3: Vklop | C3: Ure | D3: Postavka €/h | E3: Dodatni stroški | F3: Znesek | G3: Ure (vklop)
A4: Surov 3D-sken (OBJ/STL) | B4: NE | C4: 0 | D4: ='Cenik storitev'!$B$3 | E4: 0 | F4: =IF(B4="DA",C4*D4+E4,0) | G4: =IF(B4="DA",C4,0)
A5: Očiščen in popravljen STL | B5: NE | C5: 0 | D5: ='Cenik storitev'!$B$4 | E5: 0 | F5: =IF(B5="DA",C5*D5+E5,0) | G5: =IF(B5="DA",C5,0)
A6: CAD-model izvožen v STL | B6: NE | C6: 0 | D6: ='Cenik storitev'!$B$5 | E6: 0 | F6: =IF(B6="DA",C6*D6+E6,0) | G6: =IF(B6="DA",C6,0)
A7: Parametrični CAD-model, STEP | B7: NE | C7: 0 | D7: ='Cenik storitev'!$B$5 | E7: 0 | F7: =IF(B7="DA",C7*D7+E7,0) | G7: =IF(B7="DA",C7,0)
A8: Rekonstrukcija STEP iz skena | B8: NE | C8: 0 | D8: ='Cenik storitev'!$B$6 | E8: 0 | F8: =IF(B8="DA",C8*D8+E8,0) | G8: =IF(B8="DA",C8,0)
A9: Celoten paket STL + STEP + dokumentacija | B9: NE | C9: 0 | D9: ='Cenik storitev'!$B$5 | E9: 0 | F9: =IF(B9="DA",C9*D9+E9,0) | G9: =IF(B9="DA",C9,0)
A10: Skupaj | F10: =SUM(F4:F9) | G10: =SUM(G4:G9)
A12: Pravice
A13: Samo fizični izdelek, brez datotek | B13: DA
A14: Datoteka za osebno uporabo naročnika | B14: NE
A15: Pravica do komercialne uporabe | B15: NE
A16: Prenos izvorne CAD-datoteke | B16: NE
A18: Postavka STEP iz CAD (vrstica 7) in rekonstrukcija iz skena (vrstica 8) sta ločeni. Pravice vplivajo na ceno le prek ur in dodatnih stroškov.
A20: Samodejna cena datoteke iz ur storitev (Kalkulator C26:C29)
A21: Vrsta datoteke (Brez / STL / STEP) | B21: Brez | E21: STL = sken + urejanje | F21: =Kalkulator!$C$26*'Cenik storitev'!$B$3+Kalkulator!$C$27*'Cenik storitev'!$B$4
A22: Prodaja (Z naročilom / Samostojno / Ponovna) | B22: Z naročilom | E22: STEP = STL + CAD + zahtevni CAD | F22: =F21+Kalkulator!$C$28*'Cenik storitev'!$B$5+Kalkulator!$C$29*'Cenik storitev'!$B$6
A23: Ročna cena € (prazno = predlog) | E23: Prvotna cena izbrane datoteke | F23: =IF(B21="STL",F21,IF(B21="STEP",F22,0))
E24: Predlog | F24: =IF(B21="Brez",0,IF(B22="Z naročilom",'Cenik storitev'!$B$14,IF(B22="Ponovna",F23*'Cenik storitev'!$B$15/100,F23)))
E25: CENA DATOTEKE (pred popustom stopnje) | F25: =IF(AND(B21<>"Brez",ISNUMBER(B23)),B23,F24)
E26: Sken/urejanje ni obračunano kot storitev (1 = da) | F26: =IF(AND(B21<>"Brez",B22<>"Z naročilom"),1,0)
E27: CAD ni obračunan kot storitev (1 = da) | F27: =IF(AND(F26=1,B21="STEP"),1,0)
A28: Z naročilom: storitve so že obračunane, datoteka zastonj ali samo predaja. Samostojno/Ponovna: ure skena/CAD so v ceni datoteke in se ne obračunajo še kot storitve.

Sheet Projekti
A1: Projekti
A3: Datum | B3: Projekt | C3: Stranka | D3: Način | E3: Status | F3: Končna cena | G3: Stroški | H3: Zaslužek | I3: Ure ocena | J3: Ure dejansko | K3: Material g ocena | L3: Material g dejansko | M3: Opomba
A4: 46320 | B4: Nosilci lučk – 2 leva + 2 desna | C4: Demo | D4: Stranka | E4: Osnutek | F4: 132.22 | G4: 35.49 | H4: 72.58 | I4: 3.5 | K4: 768 | M4: demo
A62: Vnesi vrednosti iz Kalkulatorja (Kopiraj → Prilepi kot vrednosti), da se zgodovinske ponudbe ne spremenijo.
